Workbook

Sheet Summary
A1: AFTERSALES STANDARDS COMPLIANCE AUDIT FORM FY2025
B3: Dealer: | C3: =VLOOKUP(C5,Sheet1!A:B,2,0) -> #N/A | F3: Date:
B5: Outlet: | F5: Auditor:
A7: Overall Audit Score
A8: No. | B8: Category | D8: Total | E8: Score | F8: % Score | G8: Rating
A9: 1 | B9: Basic | D9: =COUNTIF('Main Form'!$B$3:$B$92,Summary!B9)-COUNTIFS('Main Form'!$B$3:$B$92,Summary!B9,'Main Form'!$P$3:$P$92,"N/A") -> 8 | E9: =COUNTIF('Main Form'!$P$3:$P$92,B9) -> 0 | F9: =E9/D9 -> 0 | G9: =IF(F9<100%,"FAIL", "PASS") -> FAIL
A10: 2 | B10: Standard | D10: =COUNTIF('Main Form'!$B$3:$B$92,Summary!B10)-COUNTIFS('Main Form'!$B$3:$B$92,Summary!B10,'Main Form'!$P$3:$P$92,"N/A") -> 63 | E10: =COUNTIF('Main Form'!$P$3:$P$92,B10) -> 0 | F10: =E10/D10 -> 0 | G10: =IF(F10<80%,"FAIL", "PASS") -> FAIL
A11: 3 | B11: Beyond | D11: =COUNTIF('Main Form'!$B$3:$B$92,Summary!B11)-COUNTIFS('Main Form'!$B$3:$B$92,Summary!B11,'Main Form'!$P$3:$P$92,"N/A") -> 4 | E11: =COUNTIF('Main Form'!$P$3:$P$92,B11) -> 0 | F11: =E11/D11 -> 0
A12: TOTAL: | D12: =SUM(D9:D11) -> 75 | E12: =SUM(E9:E11) -> 0 | F12: =E12/D12 -> 0 | G12: =IF(F12<80%,"FAIL",IF(OR(G9="FAIL",G10="FAIL",G11="FAIL"),"FAIL","PASS")) -> FAIL
A14: Compliance Per Category
A15: No. | B15: Coverage | D15: Total | E15: Score | F15: % Score
A16: 1 | B16: Facilities | D16: =COUNTIF('Main Form'!$C$3:$C$92,Summary!B16)-COUNTIFS('Main Form'!$C$3:$C$92,Summary!B16,'Main Form'!$Q$3:$Q$92,"N/A") -> 12 | E16: =COUNTIFS('Main Form'!$Q$3:$Q$92,B16) -> 0 | F16: =E16/D16 -> 0
A17: 2 | B17: Systems | D17: =COUNTIF('Main Form'!$C$3:$C$92,Summary!B17)-COUNTIFS('Main Form'!$C$3:$C$92,Summary!B17,'Main Form'!$Q$3:$Q$92,"N/A") -> 4 | E17: =COUNTIFS('Main Form'!$Q$3:$Q$92,B17) -> 0 | F17: =E17/D17 -> 0
A18: 3 | B18: Manpower | D18: =COUNTIF('Main Form'!$C$3:$C$92,Summary!B18)-COUNTIFS('Main Form'!$C$3:$C$92,Summary!B18,'Main Form'!$Q$3:$Q$92,"N/A") -> 5 | E18: =COUNTIFS('Main Form'!$Q$3:$Q$92,B18) -> 0 | F18: =E18/D18 -> 0
A19: 4 | B19: Pro-active Customer Contact | D19: =COUNTIF('Main Form'!$C$3:$C$92,Summary!B19)-COUNTIFS('Main Form'!$C$3:$C$92,Summary!B19,'Main Form'!$Q$3:$Q$92,"N/A") -> 3 | E19: =COUNTIFS('Main Form'!$Q$3:$Q$92,B19) -> 0 | F19: =E19/D19 -> 0
A20: 5 | B20: Customer Appointment | D20: =COUNTIF('Main Form'!$C$3:$C$92,Summary!B20)-COUNTIFS('Main Form'!$C$3:$C$92,Summary!B20,'Main Form'!$Q$3:$Q$92,"N/A") -> 5 | E20: =COUNTIFS('Main Form'!$Q$3:$Q$92,B20) -> 0 | F20: =E20/D20 -> 0
A21: 6 | B21: Personalized Customer Reception | D21: =COUNTIF('Main Form'!$C$3:$C$92,Summary!B21)-COUNTIFS('Main Form'!$C$3:$C$92,Summary!B21,'Main Form'!$Q$3:$Q$92,"N/A") -> 8 | E21: =COUNTIFS('Main Form'!$Q$3:$Q$92,B21) -> 0 | F21: =E21/D21 -> 0
A22: 7 | B22: Menu Pricing / Commitment of Price and Time Delivery | D22: =COUNTIF('Main Form'!$C$3:$C$92,Summary!B22)-COUNTIFS('Main Form'!$C$3:$C$92,Summary!B22,'Main Form'!$Q$3:$Q$92,"N/A") -> 3 | E22: =COUNTIFS('Main Form'!$Q$3:$Q$92,B22) -> 0 | F22: =E22/D22 -> 0
A23: 8 | B23: Customer Care and Communication | D23: =COUNTIF('Main Form'!$C$3:$C$92,Summary!B23)-COUNTIFS('Main Form'!$C$3:$C$92,Summary!B23,'Main Form'!$Q$3:$Q$92,"N/A") -> 7 | E23: =COUNTIFS('Main Form'!$Q$3:$Q$92,B23) -> 0 | F23: =E23/D23 -> 0
A24: 9 | B24: Workshop Scheduling | D24: =COUNTIF('Main Form'!$C$3:$C$92,Summary!B24)-COUNTIFS('Main Form'!$C$3:$C$92,Summary!B24,'Main Form'!$Q$3:$Q$92,"N/A") -> 5 | E24: =COUNTIFS('Main Form'!$Q$3:$Q$92,B24) -> 0 | F24: =E24/D24 -> 0
A25: 10 | B25: Advance Info to Parts Store | D25: =COUNTIF('Main Form'!$C$3:$C$92,Summary!B25)-COUNTIFS('Main Form'!$C$3:$C$92,Summary!B25,'Main Form'!$Q$3:$Q$92,"N/A") -> 2 | E25: =COUNTIFS('Main Form'!$Q$3:$Q$92,B25) -> 0 | F25: =E25/D25 -> 0
A26: 11 | B26: Repair Order Processing and Quality of Work | D26: =COUNTIF('Main Form'!$C$3:$C$92,Summary!B26)-COUNTIFS('Main Form'!$C$3:$C$92,Summary!B26,'Main Form'!$Q$3:$Q$92,"N/A") -> 4 | E26: =COUNTIFS('Main Form'!$Q$3:$Q$92,B26) -> 0 | F26: =E26/D26 -> 0
A27: 12 | B27: Repair Order Completion and Invoicing | D27: =COUNTIF('Main Form'!$C$3:$C$92,Summary!B27)-COUNTIFS('Main Form'!$C$3:$C$92,Summary!B27,'Main Form'!$Q$3:$Q$92,"N/A") -> 4 | E27: =COUNTIFS('Main Form'!$Q$3:$Q$92,B27) -> 0 | F27: =E27/D27 -> 0
A28: 13 | B28: Customer Information and Car Return | D28: =COUNTIF('Main Form'!$C$3:$C$92,Summary!B28)-COUNTIFS('Main Form'!$C$3:$C$92,Summary!B28,'Main Form'!$Q$3:$Q$92,"N/A") -> 5 | E28: =COUNTIFS('Main Form'!$Q$3:$Q$92,B28) -> 0 | F28: =E28/D28 -> 0 | L28: x
A29: 14 | B29: Customer After Service Contact | D29: =COUNTIF('Main Form'!$C$3:$C$92,Summary!B29)-COUNTIFS('Main Form'!$C$3:$C$92,Summary!B29,'Main Form'!$Q$3:$Q$92,"N/A") -> 3 | E29: =COUNTIFS('Main Form'!$Q$3:$Q$92,B29) -> 0 | F29: =E29/D29 -> 0
A30: 15 | B30: Concern Prevention and Resolution | D30: =COUNTIF('Main Form'!$C$3:$C$92,Summary!B30)-COUNTIFS('Main Form'!$C$3:$C$92,Summary!B30,'Main Form'!$Q$3:$Q$92,"N/A") -> 5 | E30: =COUNTIFS('Main Form'!$Q$3:$Q$92,B30) -> 0 | F30: =E30/D30 -> 0
A31: Total: | D31: =SUM(D16:D30) -> 75 | E31: =SUM(E16:E30) -> 0 | F31: =E31/D31 -> 0

Sheet Main Form
A2: No. | B2: Category | C2: Coverage | D2: Subject | E2: Check Item | F2: Person Accountable | G2: Checker | H2: Judgment | I2: Findings | J2: BOM Task | K2: Escalation | L2: Action Plan | M2: Commitment Date | N2: Count NA | O2: Audit Result Part 1 | P2: Audit Result Part 2
A3: 1 | B3: Standard | C3: Manpower | D3: Manpower Count | E3: Check accuracy of manpower list from latest submission to Network Training Department (NTD). | F3: GM | G3: ASM | H3: NO | I3: hindi accurate ang list info | J3: follow up action plan and monitor compliance | K3: AS BRAND HEAD | N3: =IF(NOT(H3="N/A"),B3,"N/A") -> Standard | O3: =IF(H3="YES",B3,IF(H3="N/A","N/A","NO")) -> NO | P3: =IF(H3="YES",C3,IF(H3="N/A","N/A","NO")) -> NO
A4: 2 | B4: Standard | C4: Manpower | D4: Training Requirements | E4: Dealer has at least 1 designated Aftersales Training person in charge. | F4: GM | G4: ASM | H4: NO | I4: no designated trainor | J4: follow up action plan and monitor compliance | K4: AS HEAD | N4: =IF(NOT(H4="N/A"),B4,"N/A") -> Standard | O4: =IF(H4="YES",B4,IF(H4="N/A","N/A","NO")) -> NO | P4: =IF(H4="YES",C4,IF(H4="N/A","N/A","NO")) -> NO
A5: 3 | B5: Standard | C5: Manpower | D5: Training Requirements | E5: All Customer Relations Department personnel are accredited following these timelines: *Level 1: within 30 days upon hiring *Level 2: within 3-6 months upon hiring *Level 3: within 1 year upon hiring | F5: GM | G5: ASM | H5: NO | I5: pending accreditation | J5: follow up action plan and monitor compliance | K5: CE CENTRAL | N5: =IF(NOT(H5="N/A"),B5,"N/A") -> Standard | O5: =IF(H5="YES",B5,IF(H5="N/A","N/A","NO")) -> NO | P5: =IF(H5="YES",C5,IF(H5="N/A","N/A","NO")) -> NO
A6: 4 | B6: Standard | C6: Pro-active Customer Contact | D6: Offering of date and time | E6: Does Telemarketer follow standard appointment balance for the day? | F6: GM | G6: ASM | H6: NO | I6: appointment for the day excceeded maximum | J6: follow up action plan and monitor compliance | K6: AS BRAND HEAD | N6: =IF(NOT(H6="N/A"),B6,"N/A") -> Standard | O6: =IF(H6="YES",B6,IF(H6="N/A","N/A","NO")) -> NO | P6: =IF(H6="YES",C6,IF(H6="N/A","N/A","NO")) -> NO
A7: 5 | B7: Standard | C7: Pro-active Customer Contact | D7: Reason of Rejection | E7: Does Telemarketer record reason of rejection in case customer do not accept PMS appointment. | F7: GM | G7: ASM | H7: NO | J7: follow up action plan and monitor compliance | K7: AS BRAND HEAD | N7: =IF(NOT(H7="N/A"),B7,"N/A") -> Standard | O7: =IF(H7="YES",B7,IF(H7="N/A","N/A","NO")) -> NO | P7: =IF(H7="YES",C7,IF(H7="N/A","N/A","NO")) -> NO
A8: 6 | B8: Standard | C8: Pro-active Customer Contact | D8: Contact Details | E8: The CRO and Service Advisor should have a printed QR Code of contact number or hotline number visible to the customers. | F8: GM | G8: ASM | H8: NO | J8: follow up action plan and monitor compliance | K8: CE CENTRAL | N8: =IF(NOT(H8="N/A"),B8,"N/A") -> Standard | O8: =IF(H8="YES",B8,IF(H8="N/A","N/A","NO")) -> NO | P8: =IF(H8="YES",C8,IF(H8="N/A","N/A","NO")) -> NO
A9: 7 | B9: Standard | C9: Customer Appointment | D9: Blocking of SA for Walk-In customer | E9: Does Telemarketer perform block time for walk-in customers? | F9: GM | G9: ASM | H9: NO | J9: follow up action plan and monitor compliance | K9: AS BRAND HEAD | N9: =IF(NOT(H9="N/A"),B9,"N/A") -> Standard | O9: =IF(H9="YES",B9,IF(H9="N/A","N/A","NO")) -> NO | P9: =IF(H9="YES",C9,IF(H9="N/A","N/A","NO")) -> NO
A10: 8 | B10: Basic | C10: Customer Appointment | D10: SA assignment | E10: Does Telemarketer assign and inform each SA their assigned customer with their appointment time? | F10: GM | G10: ASM | H10: NO | J10: follow up action plan and monitor compliance | K10: AS BRAND HEAD | N10: =IF(NOT(H10="N/A"),B10,"N/A") -> Basic | O10: =IF(H10="YES",B10,IF(H10="N/A","N/A","NO")) -> NO | P10: =IF(H10="YES",C10,IF(H10="N/A","N/A","NO")) -> NO
A11: 9 | B11: Standard | C11: Customer Appointment | D11: Reconfirmation Call | E11: Does Telemarketer make appointment reconfirmation call the day before? | F11: GM | G11: ASM | H11: NO | J11: follow up action plan and monitor compliance | K11: AS BRAND HEAD | N11: =IF(NOT(H11="N/A"),B11,"N/A") -> Standard | O11: =IF(H11="YES",B11,IF(H11="N/A","N/A","NO")) -> NO | P11: =IF(H11="YES",C11,IF(H11="N/A","N/A","NO")) -> NO
A12: 10 | B12: Basic | C12: Systems | D12: Otoleap Booking Management | E12: There should be no pending bookings more than 24hrs after it was created (Otoleap) | F12: GM | G12: ASM | H12: NO | J12: follow up action plan and monitor compliance | K12: CE CENTRAL | N12: =IF(NOT(H12="N/A"),B12,"N/A") -> Basic | O12: =IF(H12="YES",B12,IF(H12="N/A","N/A","NO")) -> NO | P12: =IF(H12="YES",C12,IF(H12="N/A","N/A","NO")) -> NO
A13: 11 | B13: Standard | C13: Customer Appointment | D13: Appointment Welcome Board | E13: Is the Appointment Welcome board visible to customer? With complete details as follows: 1) today's date 2) time slot 3) name or plate number of customer 4) SA name 5) purpose of visit: e.g. 10K PMS, GR, etc. 6) Arrival Status (Green - On time, Yellow - Late, Red - No Show) | F13: GM | G13: ASM | H13: NO | J13: follow up action plan and monitor compliance | K13: AS BRAND HEAD | N13: =IF(NOT(H13="N/A"),B13,"N/A") -> Standard | O13: =IF(H13="YES",B13,IF(H13="N/A","N/A","NO")) -> NO | P13: =IF(H13="YES",C13,IF(H13="N/A","N/A","NO")) -> NO
A14: 12 | B14: Basic | C14: Customer Appointment | D14: Appointment | E14: Telemarketer shares the list of customers booked 1 day before the day of appointment to all concerned after-sales personnel (Security Guard, Job Controller, Leadman, Parts Warehouse Staff, Service Advisor, Service Manager, Sales Executive - optional) | F14: GM | G14: ASM | H14: NO | J14: follow up action plan and monitor compliance | K14: AS BRAND HEAD | N14: =IF(NOT(H14="N/A"),B14,"N/A") -> Basic | O14: =IF(H14="YES",B14,IF(H14="N/A","N/A","NO")) -> NO | P14: =IF(H14="YES",C14,IF(H14="N/A","N/A","NO")) -> NO
A15: 13 | B15: Standard | C15: Facilities | D15: Dedicated Appointment and Walk-In Bay | E15: Is there dedicated appointment bay and walk in receiving bays? | F15: GM | G15: ASM | H15: NO | J15: follow up action plan and monitor compliance | K15: AS BRAND HEAD | N15: =IF(NOT(H15="N/A"),B15,"N/A") -> Standard | O15: =IF(H15="YES",B15,IF(H15="N/A","N/A","NO")) -> NO | P15: =IF(H15="YES",C15,IF(H15="N/A","N/A","NO")) -> NO
A16: 14 | B16: Standard | C16: Manpower | D16: Customer Relations Department | E16: Customer Relations Department (CRO, Receptionist, Telemarketer) personnel count must be based on the standard requirements. | F16: GM | G16: ASM | H16: NO | J16: follow up action plan and monitor compliance | K16: AS BRAND HEAD | N16: =IF(NOT(H16="N/A"),B16,"N/A") -> Standard | O16: =IF(H16="YES",B16,IF(H16="N/A","N/A","NO")) -> NO | P16: =IF(H16="YES",C16,IF(H16="N/A","N/A","NO")) -> NO
A17: 15 | B17: Basic | C17: Personalized Customer Reception | D17: Queuing system | E17: Is there a queuing system in the reception area? | F17: GM | G17: ASM | H17: NO | J17: follow up action plan and monitor compliance | K17: CE CENTRAL | N17: =IF(NOT(H17="N/A"),B17,"N/A") -> Basic | O17: =IF(H17="YES",B17,IF(H17="N/A","N/A","NO")) -> NO | P17: =IF(H17="YES",C17,IF(H17="N/A","N/A","NO")) -> NO
A18: 16 | B18: Standard | C18: Personalized Customer Reception | D18: Peak hours | E18: Is there a Receptionist who will accommodate customer during peak hours or if all SA's are still accomodating the customers? | F18: GM | G18: ASM | H18: NO | J18: follow up action plan and monitor compliance | K18: CE CENTRAL | N18: =IF(NOT(H18="N/A"),B18,"N/A") -> Standard | O18: =IF(H18="YES",B18,IF(H18="N/A","N/A","NO")) -> NO | P18: =IF(H18="YES",C18,IF(H18="N/A","N/A","NO")) -> NO
... A33: 31 | B33: Beyond | C33: Customer Care and Communication | D33: Shuttle Service Assistance | E33: Does the SA offer shuttle service transportation or assistance (e.g. grab, taxi etc…)? | F33: ASM | G33: CE SERVICE | H33: NO | J33: follow up action plan and monitor compliance | K33: GM | N33: =IF(NOT(H33="N/A"),B33,"N/A") -> Beyond | O33: =IF(H33="YES",B33,IF(H33="N/A","N/A","NO")) -> NO | P33: =IF(H33="YES",C33,IF(H33="N/A","N/A","NO")) -> NO
A34: 32 | B34: Beyond | C34: Customer Care and Communication | D34: Assigned Sales Executive | E34: Did salesperson make contact with customer who was waiting at the lounge? 150K > offer new vehicle | F34: GM | G34: CE SERVICE | H34: NO | J34: - Check if the Assigned Agent for Service Reception for the day is present and is talking to the prospective client/s. - Accessible table for Sales Agent assigned in the Service reception area. - follow up action plan and monitor compliance. | K34: Brand Head | N34: =IF(NOT(H34="N/A"),B34,"N/A") -> Beyond | O34: =IF(H34="YES",B34,IF(H34="N/A","N/A","NO")) -> NO | P34: =IF(H34="YES",C34,IF(H34="N/A","N/A","NO")) -> NO | R34: - Sales team need to provide Sales Agent assigned in Service Reception Area - Sales Agents must be able to talk to at least 30% of the scheduled clients for the day. - CE must generate report of show up list at the start of the day to identify clients with 5 yrs and up aged vehicles.
A35: 33 | B35: Standard | C35: Customer Care and Communication | D35: Service Advisor | E35: Does SA inform progress of vehicle to the waiting customer 1 hr after issuance of RO? | F35: ASM | G35: CE SERVICE | H35: NO | J35: - BOM to seek report from CE to check if there are any non-compliance - Follow up action plan and monitor compliance | K35: GM | N35: =IF(NOT(H35="N/A"),B35,"N/A") -> Standard | O35: =IF(H35="YES",B35,IF(H35="N/A","N/A","NO")) -> NO | P35: =IF(H35="YES",C35,IF(H35="N/A","N/A","NO")) -> NO | R35: Checker must conduct random audit by talking to customers and asking if SA was able to inform them of the Status of their transaction
A36: 34 | B36: Standard | C36: Customer Care and Communication | D36: Customer Information Sheet | E36: Customer Information Sheet (CIS) and DPA Form is being used by Receptionist to gather customer contact information as needed. | F36: ASM | G36: CE SERVICE | H36: NO | J36: - Check completeness of CIS follow up action plan and monitor compliance | K36: GM | N36: =IF(NOT(H36="N/A"),B36,"N/A") -> Standard | O36: =IF(H36="YES",B36,IF(H36="N/A","N/A","NO")) -> NO | P36: =IF(H36="YES",C36,IF(H36="N/A","N/A","NO")) -> NO
A37: 35 | B37: Standard | C37: Workshop Scheduling | D37: Job Progress Monitoring | E37: Did the Job Controller conduct pre-planning based on the appointment sheet for the day and regularly monitors actual progress of units in the shop? | F37: GM | G37: ASM | H37: NO | J37: - Check Job Con Monitoring report follow up action plan and monitor compliance | K37: AS BRAND HEAD | N37: =IF(NOT(H37="N/A"),B37,"N/A") -> Standard | O37: =IF(H37="YES",B37,IF(H37="N/A","N/A","NO")) -> NO | P37: =IF(H37="YES",C37,IF(H37="N/A","N/A","NO")) -> NO
A38: 36 | B38: Standard | C38: Workshop Scheduling | D38: Carwash Control Board | E38: Is car wash control board available, properly filled out and based on the standard template? | F38: ASM | G38: WORSHOP SUP | H38: NO | J38: - Check casrwash control board if updated and correct follow up action plan and monitor compliance | K38: GM | N38: =IF(NOT(H38="N/A"),B38,"N/A") -> Standard | O38: =IF(H38="YES",B38,IF(H38="N/A","N/A","NO")) -> NO | P38: =IF(H38="YES",C38,IF(H38="N/A","N/A","NO")) -> NO
A39: 37 | B39: Standard | C39: Workshop Scheduling | D39: Job Progress Monitoring | E39: Did Job Controller make car wash plan and communicate with carwasher the promised time of received customers? | F39: GM | G39: ASM | H39: NO | J39: - Check casrwash control board if actual released time matched the promised released time follow up action plan and monitor compliance | K39: AS BRAND HEAD | N39: =IF(NOT(H39="N/A"),B39,"N/A") -> Standard | O39: =IF(H39="YES",B39,IF(H39="N/A","N/A","NO")) -> NO | P39: =IF(H39="YES",C39,IF(H39="N/A","N/A","NO")) -> NO
A40: 38 | B40: Standard | C40: Workshop Scheduling | D40: Technicians Clock-In | E40: Do technicians clock in as soon as RO is handed over and clock out as soon as job is completed (excluding QC)? | F40: ASM | G40: JC | H40: NO | J40: - Verify if actual clock-in or clock-out time is recorded follow up action plan and monitor compliance | K40: GM | N40: =IF(NOT(H40="N/A"),B40,"N/A") -> Standard | O40: =IF(H40="YES",B40,IF(H40="N/A","N/A","NO")) -> NO | P40: =IF(H40="YES",C40,IF(H40="N/A","N/A","NO")) -> NO
A41: 39 | B41: Standard | C41: Workshop Scheduling | D41: Repair | E41: Carryover units are properly monitored and managed (with monitoring) by Job Controller. | F41: ASM | G41: WORSHOP SUP | H41: NO | J41: - Check job control WIP monitoring if updated and match the actual units in the workshop follow up action plan and monitor compliance | K41: GM | N41: =IF(NOT(H41="N/A"),B41,"N/A") -> Standard | O41: =IF(H41="YES",B41,IF(H41="N/A","N/A","NO")) -> NO | P41: =IF(H41="YES",C41,IF(H41="N/A","N/A","NO")) -> NO
A42: 40 | B42: Standard | C42: Advance Info to Parts Store | D42: Pre-Picking | E42: Does Parts Staff pre-pick parts for appointment and walk-in customers? | F42: ASM | G42: Parts Supervisor | H42: NO | J42: - Physical Checking of pre-picked parts of corrent follow up action plan and monitor compliance | K42: GM | N42: =IF(NOT(H42="N/A"),B42,"N/A") -> Standard | O42: =IF(H42="YES",B42,IF(H42="N/A","N/A","NO")) -> NO | P42: =IF(H42="YES",C42,IF(H42="N/A","N/A","NO")) -> NO
A43: 41 | B43: Standard | C43: Advance Info to Parts Store | D43: Emergency Parts | E43: Is there any monitoring to ensure that the Leadman/ technician who is waiting for emergency parts is contacted immediately after delivery/receiving of parts? | F43: ASM | G43: Parts Supervisor | H43: NO | J43: - Ask workshop supervisor/ leadman if they were immediately informed if emergency parts already arrived in the dealership follow up action plan and monitor compliance | K43: GM | N43: =IF(NOT(H43="N/A"),B43,"N/A") -> Standard | O43: =IF(H43="YES",B43,IF(H43="N/A","N/A","NO")) -> NO | P43: =IF(H43="YES",C43,IF(H43="N/A","N/A","NO")) -> NO
A44: 42 | B44: Standard | C44: Facilities | D44: Parts 5S | E44: Are there no parts on the floor without bin locator? And/ or does each locator stores only one kind of parts? | F44: ASM | G44: Parts Supervisor | H44: NO | J44: - Check if all parts inside the warehouse are stored with bin locators follow up action plan and monitor compliance | K44: GM | N44: =IF(NOT(H44="N/A"),B44,"N/A") -> Standard | O44: =IF(H44="YES",B44,IF(H44="N/A","N/A","NO")) -> NO | P44: =IF(H44="YES",C44,IF(H44="N/A","N/A","NO")) -> NO
A45: 43 | B45: Standard | C45: Repair Order Processing and Quality of Work | D45: Vehicle Status Tag | E45: Does Leadman indicate or instruct target job completion time to the assigned technician? | F45: ASM | G45: WORSHOP SUP | H45: NO | J45: - Check if technician visualization tag if updated by leadman and if the details on the Tag is correct vs the actual job. follow up action plan and monitor compliance | K45: GM | N45: =IF(NOT(H45="N/A"),B45,"N/A") -> Standard | O45: =IF(H45="YES",B45,IF(H45="N/A","N/A","NO")) -> NO | P45: =IF(H45="YES",C45,IF(H45="N/A","N/A","NO")) -> NO
A46: 44 | B46: Standard | C46: Repair Order Processing and Quality of Work | D46: Unapproved Job | E46: In case of unapproved job by the customer, does SA record as "future work reminder" in service history of DMS? | F46: GM | G46: ASM | H46: NO | J46: - Gather Estimate Report from ASM to check. (Do we need to allow access for BOM?) follow up action plan and monitor compliance | K46: AS BRAND HEAD | N46: =IF(NOT(H46="N/A"),B46,"N/A") -> Standard | O46: =IF(H46="YES",B46,IF(H46="N/A","N/A","NO")) -> NO | P46: =IF(H46="YES",C46,IF(H46="N/A","N/A","NO")) -> NO
A47: 45 | B47: Basic | C47: Facilities | D47: Workshop Maintenance | E47: Workbays are marked with demarcation lines, and identified with numbers; Cleanliness inside the workshop area is maintained (no lingering oil and water spills, and scattered items) | F47: ASM | G47: WORSHOP SUP | H47: NO | J47: - Visual check of cleanliness in the workshop. follow up action plan and monitor compliance | K47: GM | N47: =IF(NOT(H47="N/A"),B47,"N/A") -> Basic | O47: =IF(H47="YES",B47,IF(H47="N/A","N/A","NO")) -> NO | P47: =IF(H47="YES",C47,IF(H47="N/A","N/A","NO")) -> NO
... A65: 63 | B65: Standard | C65: Customer Information and Car Return | D65: Replaced Parts | E65: Does SA show replaced parts (if applicable) during delivery process? | F65: GM | G65: ASM | H65: NO | J65: - Check if replaced parts was returned to the customer. If not, verify if there is proper documentation for it. follow up action plan and monitor compliance | K65: AS BRAND HEAD | N65: =IF(NOT(H65="N/A"),B65,"N/A") -> Standard | O65: =IF(H65="YES",B65,IF(H65="N/A","N/A","NO")) -> NO | P65: =IF(H65="YES",C65,IF(H65="N/A","N/A","NO")) -> NO
A66: 64 | B66: Standard | C66: Customer Information and Car Return | D66: QVOC Reminder | E66: Does Service Advisor remind the customer regarding QVOC? | F66: ASM | G66: CE SERVICE | H66: NO | J66: follow up action plan and monitor compliance | K66: AS BRAND HEAD | N66: =IF(NOT(H66="N/A"),B66,"N/A") -> Standard | O66: =IF(H66="YES",B66,IF(H66="N/A","N/A","NO")) -> NO | P66: =IF(H66="YES",C66,IF(H66="N/A","N/A","NO")) -> NO | R66: Check if we can find way on how to verify if implmented or not
A67: 65 | B67: Standard | C67: Customer Information and Car Return | D67: Removal of Protective Cover | E67: Does SA remove the Protective Cover Sheet in the presence of Customer before vehicle is delivered back to the Customer? | F67: ASM | G67: WORSHOP SUP | H67: NO | J67: - check with security if covers are removed in the presence of customers. follow up action plan and monitor compliance | K67: GM | N67: =IF(NOT(H67="N/A"),B67,"N/A") -> Standard | O67: =IF(H67="YES",B67,IF(H67="N/A","N/A","NO")) -> NO | P67: =IF(H67="YES",C67,IF(H67="N/A","N/A","NO")) -> NO | R67: Inform security to check if protective covers are reemoved in front of the customer
A68: 66 | B68: Standard | C68: Customer Information and Car Return | D68: Follow-Up Call | E68: Does SA mention about the follow up call and its purpose such as the following? > to give notice to the customer that follow up call will be made by CRO within 3 days > benefit of the follow up call for customer > preferable time to receive a call | F68: ASM | G68: CE SERVICE | H68: NO | J68: follow up action plan and monitor compliance | K68: CE CENTRAL | N68: =IF(NOT(H68="N/A"),B68,"N/A") -> Standard | O68: =IF(H68="YES",B68,IF(H68="N/A","N/A","NO")) -> NO | P68: =IF(H68="YES",C68,IF(H68="N/A","N/A","NO")) -> NO | R68: Check if we can find way on how to verify if implmented or not
A69: 67 | B69: Standard | C69: Customer After Service Contact | D69: Follow-Up Call | E69: Does CRO conduct 3 days after service follow up calls? | F69: GM | G69: ASM | H69: NO | J69: follow up action plan and monitor compliance | K69: AS BRAND HEAD | N69: =IF(NOT(H69="N/A"),B69,"N/A") -> Standard | O69: =IF(H69="YES",B69,IF(H69="N/A","N/A","NO")) -> NO | P69: =IF(H69="YES",C69,IF(H69="N/A","N/A","NO")) -> NO | R69: Check if we can find way on how to verify if implmented or not
A70: 68 | B70: Standard | C70: Customer After Service Contact | D70: Complaint Monitoring Tracking Report | E70: Does CRO categorize concerns based on follow up call result and collected QVOC responses? (i.e. concern on parking, attitude of staff, quality of work, price of RO etc.) | F70: GM | G70: ASM | H70: NO | J70: follow up action plan and monitor compliance | K70: AS BRAND HEAD | N70: =IF(NOT(H70="N/A"),B70,"N/A") -> Standard | O70: =IF(H70="YES",B70,IF(H70="N/A","N/A","NO")) -> NO | P70: =IF(H70="YES",C70,IF(H70="N/A","N/A","NO")) -> NO | R70: Check if we can find way on how to verify if implmented or not
A71: 69 | B71: Standard | C71: Customer After Service Contact | D71: Complaint Monitoring Tracking Report | E71: Does the Complaint Monitoring Tracking Report include open concern (concern that has no implemented action within 7 calendar days). | F71: GM | G71: ASM | H71: NO | J71: follow up action plan and monitor compliance | K71: AS BRAND HEAD | N71: =IF(NOT(H71="N/A"),B71,"N/A") -> Standard | O71: =IF(H71="YES",B71,IF(H71="N/A","N/A","NO")) -> NO | P71: =IF(H71="YES",C71,IF(H71="N/A","N/A","NO")) -> NO | R71: Check if we can find way on how to verify if implmented or not
A72: 70 | B72: Standard | C72: Concern Prevention and Resolution | D72: MAM | E72: Is "Weekly Meeting" (MAM) organized at least once a week at the same time on the same day of week? | F72: GM | G72: ASM | H72: NO | J72: - Check MAM template filled-out form follow up action plan and monitor compliance | K72: AS BRAND HEAD | N72: =IF(NOT(H72="N/A"),B72,"N/A") -> Standard | O72: =IF(H72="YES",B72,IF(H72="N/A","N/A","NO")) -> NO | P72: =IF(H72="YES",C72,IF(H72="N/A","N/A","NO")) -> NO
...

Sheet Subform
A1: Judgment | C1: Service Reception c/o CE
A2: 1 | B2: YES | C2: Service Reception signage follows the standard design, and must be clearly displayed at the entrance
A3: 2 | B3: NO | C3: Business hours clearly displayed at the entrance door
A4: 3 | B4: NO | C4: Three (3) monitors (with 42" minimum dimension) are wall-mounted behind the Service Advisor counters, and displays service information and promotional videos | D4: CSI
A5: 4 | B5: NO | C5: Service hotlines (appointment, customer, car carrier) and MM360c App QR codes are clearly displayed at the Reception Area
A6: 5 | B6: NO | C6: Must be provided with proper AC temperature (must be minimum of 25°C in thermometer) for customers' convenience
A7: 6 | B7: NO | C7: Service reception counter must observe 5S (mainly service advisor's table) | D7: CSI
A8: 7 | B8: NO | C8: Standard PMS menu and cost are displayed in the center monitor
A9: 8 | B9: NO | C9: Receptionist/SA on duty must be located near the entrance.
A10: 9 | B10: NO | C10: Must have sufficient illumination (open lights during operations) and no busted lights
A11: Judgment | C11: Employee Facilities c/o WS/Foreman/Leadman
A12: 1 | B12: YES | C12: Employees' Restroom (Maintained clean and must have the proper amenities for convenience of use i.e. soap, water supply, tissue, etc.)
A13: 2 | B13: NO | C13: Technician Locker Room and Shower are adjacent with each other
A14: 3 | B14: NO | C14: Sufficient no. of technicians' lockers
A15: 4 | B15: NO | C15: Technician Locker Room has sufficient no. of tables and benches
A16: 5 | B16: NO | C16: Technician Locker Room walls and flooring must have proper paint
A17: 6 | B17: NO | C17: Technician Locker Room has proper lighting and ventilation
A18: 7 | B18: NO | C18: Technician Shower Room has sufficient no. of showers, urinals, and toilet cubicle
A19: 8 | B19: NO | C19: Technician Shower Room has clean toilets bowls with flush, bidet, tissue and soap
A20: 9 | B20: NO | C20: Technician shower and toilets are completely functional
A21: 10 | B21: NO | C21: Technician waiting area (Near the Job Controller room for efficient job order dispatch)
A22: 11 | B22: NO | C22: Technician waiting area (Sufficient benches)
A23: 12 | B23: NO | C23: Technician handwash booth (Adequate supply of water) (separate booth is optional)
A24: Judgment | C24: Meeting Room c/o ASM
A25: 1 | B25: NO | C25: Allocated Meeting/ Conference Room especially for online trainings
A26: 2 | B26: NO | C26: Available projector and PC/laptop (to be used for online trainings)
A27: 3 | B27: NO | C27: Available Wi-Fi (Internet Connection = 10mbps)
A28: Judgment | C28: Mitsubishi Quick Service (confirm first if dealer is MQS accredited, if not, tag initially as "NA") c/o WS
A29: 1 | B29: NO | C29: Dedicated MQS bay with complete MQS basic and advanced tools
A30: 2 | B30: NO | C30: Proper execution of MQS sequence
A31: 3 | B31: NO | C31: Check 1 sample of MQS vehicle if within prescribed time
A32: 4 | B32: NO | C32: MQS technician must be provided with complete QS uniforms
A33: Judgment | C33: Customer's Lounge c/o CE
A34: 1 | B34: NO | C34: Sofas must be sufficient, comfortable, and maintained in good condition (Refer to MMPC corporate Visual Identity (VI) manual for the color) | D34: CSI
A35: 2 | B35: NO | C35: Room temperature must be minimum of 25°C; temperature must be displayed through a thermometer | D35: CSI
A36: 3 | B36: NO | C36: Must have sufficient illumination (open lights during operations) and no busted lights
A37: 4 | B37: NO | C37: Must offer at least three kinds of complimentary beverage (water, coffee, and juice) and at least one kind of snack
A38: 5 | B38: NO | C38: Television must have media player or cable channels | D38: CSI
A39: 6 | B39: NO | C39: There's an available Wi-Fi with a speed of at least 10 Mbps when measured using speed test (Measuring tool: https://www.speedtest.net/)
A40: 7 | B40: NO | C40: There are available power outlets for mobile phone, tablet, and laptop
...

Sheet Documentation
A1: No. | B1: Service Document | C1: Check item | D1: 1 | E1: 2 | F1: 3
C2: R.O. Number
C3: Type of Job (mileage)
A4: 1 | B4: Rationalized Checksheet | C4: Uses latest Rationalized Checksheet (5k or 10k) | D4: YES | E4: NO | F4: NO
C5: Complete Name and Plate Number | D5: NO | E5: NO | F5: NO
C6: PMS checklist is properly filled-out | D6: NO | E6: NO | F6: NO
C7: Safety checklist is properly filled-out | D7: NO | E7: NO | F7: NO
C8: Carwash checklist is properly filled-out | D8: NO | E8: NO | F8: NO
C9: Final walk-around inspection checklist is properly filled-out | D9: NO | E9: NO | F9: NO
C10: 10pts. Service Advisor Checklist is properly filled-out | D10: NO | E10: NO | F10: NO
C11: With SA' Signature | D11: NO | E11: NO | F11: NO
C12: With Technician's signature | D12: NO | E12: NO | F12: NO
C13: With Leadman's signature | D13: NO | E13: NO | F13: NO
C14: With customer's signature | D14: NO | E14: NO | F14: NO
A15: 2 | B15: Repair Order | C15: Complete customer and vehicle details | D15: NO | E15: NO | F15: NO
C16: Promised time of delivery is indicated | D16: NO | E16: NO | F16: NO
C17: With Customer's signature | D17: NO | E17: NO | F17: YES
A18: 3 | B18: Service Invoice | C18: Date/time actual repair time is indicated | D18: NO | E18: NO | F18: NO
C19: Customer's and SA's signature | D19: NO | E19: NO | F19: NO
C20: Next PMS Schedule is indicated with MM360c App booking code | D20: NO | E20: YES | F20: NO

Sheet How To Check
A2: No. | B2: Category | C2: Coverage | D2: Subject | E2: Check Item | F2: How to Check
A3: 1 | B3: Standard | C3: Manpower | D3: Manpower Count | E3: Check accuracy of manpower list from latest submission to Network Training Department (NTD). | F3: Check if latest submitted file of manpower list is accurate with actual manpower allocation.
A4: 2 | B4: Standard | C4: Manpower | D4: Training Requirements | E4: Dealer has at least 1 designated Aftersales Training person in charge. | F4: Verify if dealer have assigned 1 Aftersales Training PIC as aligned with MMPC NTD Database.
A5: 3 | B5: Standard | C5: Manpower | D5: Training Requirements | E5: All Customer Relations Department personnel are accredited following these timelines: *Level 1: within 30 days upon hiring *Level 2: within 3-6 months upon hiring *Level 3: within 1 year upon hiring | F5: Check the training record from Training Department
A6: 4 | B6: Standard | C6: Pro-active Customer Contact | D6: Offering of date and time | E6: Does Telemarketer follow standard appointment balance for the day? | F6: Check Appointment balance if: Morning = 80% Afternoon = 20%
A7: 5 | B7: Standard | C7: Pro-active Customer Contact | D7: Reason of Rejection | E7: Does Telemarketer record reason of rejection in case customer do not accept PMS appointment. | F7: Check if there's a printed Customer Rejection Countermeasure and observe if utilized during call activities.
A8: 6 | B8: Standard | C8: Pro-active Customer Contact | D8: Contact Details | E8: The CRO and Service Advisor should have a printed QR Code of contact number or hotline number visible to the customers. | F8: Check if there's a printed QR Code of contact number or hotline number visible to the customers: 1. Telemarketer's hotline - for service appointment 2. CRO - for complaints
A9: 7 | B9: Standard | C9: Customer Appointment | D9: Blocking of SA for Walk-In customer | E9: Does Telemarketer perform block time for walk-in customers? | F9: Check Appointment List if there is alloted block time for walk in.
A10: 8 | B10: Basic | C10: Customer Appointment | D10: SA assignment | E10: Does Telemarketer assign and inform each SA their assigned customer with their appointment time? | F10: Check Appointment List if there is SA allocated for each customer.
A11: 9 | B11: Standard | C11: Customer Appointment | D11: Reconfirmation Call | E11: Does Telemarketer make appointment reconfirmation call the day before? | F11: Check Appointment List if with remarks that customers have been contacted for appointment reconfirmation 1 day prior.
A12: 10 | B12: Basic | C12: Systems | D12: Otoleap Booking Management | E12: There should be no pending bookings more than 24hrs after it was created (Otoleap) | F12: Check Otoleap calendar for the same month if there are no pending bookings the days prior the day of audit.
A13: 11 | B13: Standard | C13: Customer Appointment | D13: Appointment Welcome Board | E13: Is the Appointment Welcome board visible to customer? With complete details as follows: 1) today's date 2) time slot 3) name or plate number of customer 4) SA name 5) purpose of visit: e.g. 10K PMS, GR, etc. 6) Arrival Status (Green - On time, Yellow - Late, Red - No Show) | F13: Check if based on standard template, if installed near service entrance, and visible to incoming customers inside their vehicle.
A14: 12 | B14: Basic | C14: Customer Appointment | D14: Appointment | E14: Telemarketer shares the list of customers booked 1 day before the day of appointment to all concerned after-sales personnel (Security Guard, Job Controller, Leadman, Parts Warehouse Staff, Service Advisor, Service Manager, Sales Executive - optional) | F14: Check if all mentioned service personnel have a copy of the Appointment List.
... A77: 75 | B77: Standard | C77: Concern Prevention and Resolution | D77: MAM | E77: Are the following KPI being monitored and ready to be discussed in case its necessary during "Weekly Meeting"?: MAIN KPI: 1) Actual SIU and target agreed with MMPC 2) Actual first retention rate 3) Actual P&A booking and target agreed with MMPC 4) Stock month of fast moving parts 5) Appointment ratio 6) Dead stock ratio 7) CSI Technician Report: 8) Efficiency (labor sold hr / actual worked hr) 9) Utilization (actual worked hr / available hr) 10) Productivity (efficiency x utilization) CRO/ Telemarketer: 11) Reminder call coverage ratio (actual reminder call / target reminder call) 12) Proactive call acceptance ratio (actual accepted appointment booking / called customer) 13) Follow up call ratio 14) Customer Complaint Tracking Discussion (Red alert, critical concerns) 15) Appointment balance for a day (Morning = 80%, Afternoon = 20%) Job Controller: 16) On time delivery and on time arrival ratio (from service time monitoring) Others: 17) Fix it right first time or repeat repair ratio (F1) 18) Direct reception (optional) 19) Focus item upselling (optional) | F77: Check minutes of the meeting (quality)
B78: Total

Sheet Pivot
B2: Main Category
A3: Subject | B3: Basic | C3: Standard | D3: Beyond | E3: Grand Total
A4: Workshop Driveway
A5: Workshop Maintenance
A6: Tools Storage Room
A7: Components Repair Room
A8: Waste Oil Storage
A9: Warranty Parts Storage
A10: Scrapped Parts Storage
A11: Dismantled Parts Storage
A12: Service Reception Area
A13: CRM Requirements
A14: Service Documents
A15: Employee Facilities
... A66: Grand Total

Sheet Data sheet
A1: Branch | B1: Dealer Group
A2: #VALUE! | B2: Citimotors Incorporation
A3: #VALUE! | B3: Blulebird Motor Corp.
A4: #VALUE! | B4: Avescor Motors Incorporated
A5: #VALUE! | B5: Motor Plaza Incorporated
A6: Bajada | B6: Karasia Incorporated
A7: Balintawak | B7: DCT Holdings
A8: #VALUE! | B8: Freeway Motor Sales - Baliuag
A9: #VALUE! | B9: Mizukawa Motors Corp.
A10: Bulua | B10: Fast Autotoworld Philippines Corporation - Mindanao
A11: #VALUE! | B11: Fast Autotoworld Philippines Corporation - Mindanao
A12: #VALUE! | B12: Freeway Motor Sales - Cabanatuan
A13: #VALUE! | B13: Fast Autotoworld Philippines Corporation - Mindanao
A14: #VALUE! | B14: Motor Plaza Incorporated
A15: #VALUE! | B15: Alphine Motors Corporation
A16: Cebu South | B16: Fast Autotoworld Philippines Corporation - Visayas
A17: Commonwealth | B17: Peak Motors Phils. Incorporated
A18: #VALUE! | B18: SJ Legacy Motors, Inc.
A19: Dasmariñas | B19: Jabez Motors Corporation
A20: #VALUE! | B20: Fast Autotoworld Philippines Corporation - Visayas
A21: #VALUE! | B21: Gateway Motors Cebu, Inc.
A22: FB Harrison | B22: Peak Motors Phils. Incorporated
A23: #VALUE! | B23: Mindanao Integrated Commercial Enterprises Inc.
A24: Gorordo | B24: Gateway Motors Cebu, Inc.
A25: #VALUE! | B25: Mizukawa Motors Corp.
A26: #VALUE! | B26: Avescor Motors Incorporated
A27: #VALUE! | B27: Mizukawa Motors Corp.
A28: #VALUE! | B28: Freeway Motor Sales - Cabanatuan
A29: #VALUE! | B29: Peak Motors Phils. Incorporated
A30: #VALUE! | B30: Mindanao Integrated Commercial Enterprises Inc.
A31: #VALUE! | B31: Motor Plaza Incorporated
A32: #VALUE! | B32: North Alliance Motors Corporation
A33: #VALUE! | B33: Citimotors Incorporation
A34: #VALUE! | B34: Super Fast Motors Corporation
A35: Lucena | B35: Mizukawa Motors Corp.
A36: Mactan | B36: Fast Autotoworld Philippines Corporation - Visayas
A37: #VALUE! | B37: Citimotors Incorporation
A38: #VALUE! | B38: Carworld Incorporated
A39: #VALUE! | B39: Fast Autotoworld Philippines Corporation - Visayas
A40: #VALUE! | B40: Grand Canyon Multi Holdings Inc.
...

Sheet Sheet1
A1: Branch | B1: Dealer Group
A2: #VALUE! | B2: Citimotors Incorporation
A3: #VALUE! | B3: Blulebird Motor Corp.
A4: #VALUE! | B4: Avescor Motors Incorporated
A5: #VALUE! | B5: Motor Plaza Incorporated
A6: Bajada | B6: Karasia Incorporated
A7: Balintawak | B7: DCT Holdings
A8: #VALUE! | B8: Freeway Motor Sales - Baliuag
A9: #VALUE! | B9: Mizukawa Motors Corp.
A10: Bulua | B10: Fast Autotoworld Philippines Corporation - Mindanao
A11: #VALUE! | B11: Fast Autotoworld Philippines Corporation - Mindanao
A12: #VALUE! | B12: Freeway Motor Sales - Cabanatuan
A13: #VALUE! | B13: Fast Autotoworld Philippines Corporation - Mindanao
A14: #VALUE! | B14: Motor Plaza Incorporated
A15: #VALUE! | B15: Alphine Motors Corporation
A16: Cebu South | B16: Fast Autotoworld Philippines Corporation - Visayas
A17: Commonwealth | B17: Peak Motors Phils. Incorporated
A18: #VALUE! | B18: SJ Legacy Motors, Inc.
A19: Dasmariñas | B19: Jabez Motors Corporation
A20: #VALUE! | B20: Fast Autotoworld Philippines Corporation - Visayas
A21: #VALUE! | B21: Gateway Motors Cebu, Inc.
A22: FB Harrison | B22: Peak Motors Phils. Incorporated
A23: #VALUE! | B23: Mindanao Integrated Commercial Enterprises Inc.
A24: Gorordo | B24: Gateway Motors Cebu, Inc.
A25: #VALUE! | B25: Mizukawa Motors Corp.
A26: #VALUE! | B26: Avescor Motors Incorporated
A27: #VALUE! | B27: Mizukawa Motors Corp.
A28: #VALUE! | B28: Freeway Motor Sales - Cabanatuan
A29: #VALUE! | B29: Peak Motors Phils. Incorporated
A30: #VALUE! | B30: Mindanao Integrated Commercial Enterprises Inc.
A31: #VALUE! | B31: Motor Plaza Incorporated
A32: #VALUE! | B32: North Alliance Motors Corporation
A33: #VALUE! | B33: Citimotors Incorporation
A34: #VALUE! | B34: Super Fast Motors Corporation
A35: Lucena | B35: Mizukawa Motors Corp.
A36: Mactan | B36: Fast Autotoworld Philippines Corporation - Visayas
A37: #VALUE! | B37: Citimotors Incorporation
A38: #VALUE! | B38: Carworld Incorporated
A39: #VALUE! | B39: Fast Autotoworld Philippines Corporation - Visayas
A40: #VALUE! | B40: Grand Canyon Multi Holdings Inc.
...
