Workbook

Sheet Main Form
A2: No. | B2: Category | C2: Coverage | D2: Subject | E2: Check Item | F2: Person Accountable | G2: Checker | H2: Judgment | I2: Findings | J2: BOM Task | K2: Escalation | L2: Action Plan | M2: Commitment Date | N2: Count NA | O2: Audit Result Part 1 | P2: Audit Result Part 2
A3: 1 | B3: Basic | C3: Facilities | D3: Facade | E3: Fascia or badge sign and letterings are complete, undamaged, clean, no watermarks, no obstructions, no discoloration and stains | F3: GM | G3: SALES MANAGER | H3: YES | I3: butas ang signage | J3: > Accomplish Inspection Request > Submit & Follow up with PM > Monitor progress until completion > signs completion report | K3: PM | N3: =IF(NOT(H3="N/A"),B3,"N/A") -> Basic | O3: =IF(H3="YES",B3,IF(H3="N/A","N/A","NO")) -> Basic | P3: =IF(H3="YES",C3,IF(H3="N/A","N/A","NO")) -> Facilities
A4: 2 | B4: Basic | C4: Facilities | D4: Facade | E4: Pylon (Single/Two-Post / Tower / Wall Projecting) sign/s and letterings are complete, undamaged, clean, no watermarks, no obstructions, no discoloration and stains | F4: GM | G4: SALES MANAGER | H4: YES | I4: nilipad ng bagyo ang pylon | J4: > Accomplish Inspection Request > Submit & Follow up with PM > Monitor progress until completion > signs completion report | K4: PM | N4: =IF(NOT(H4="N/A"),B4,"N/A") -> Basic | O4: =IF(H4="YES",B4,IF(H4="N/A","N/A","NO")) -> Basic | P4: =IF(H4="YES",C4,IF(H4="N/A","N/A","NO")) -> Facilities
A5: 3 | B5: Basic | C5: Facilities | D5: Facade | E5: All exterior Visual Identity including building walls, exterior paint and finishes, are clean and free from damage. | F5: GM | G5: SALES MANAGER | H5: YES | J5: > Accomplish Inspection Request > Submit & Follow up with PM > Monitor progress until completion > signs completion report | K5: PM | N5: =IF(NOT(H5="N/A"),B5,"N/A") -> Basic | O5: =IF(H5="YES",B5,IF(H5="N/A","N/A","NO")) -> Basic | P5: =IF(H5="YES",C5,IF(H5="N/A","N/A","NO")) -> Facilities
A6: 4 | B6: Basic | C6: Facilities | D6: Facade | E6: Showroom glass is clean, free from cracks, scratches, damage, dust, stains and water marks | F6: GM | G6: SALES MANAGER | H6: YES | J6: > Accomplish Inspection Request > Submit & Follow up with PM > Monitor progress until completion > signs completion report | K6: PM | N6: =IF(NOT(H6="N/A"),B6,"N/A") -> Basic | O6: =IF(H6="YES",B6,IF(H6="N/A","N/A","NO")) -> Basic | P6: =IF(H6="YES",C6,IF(H6="N/A","N/A","NO")) -> Facilities
A7: 5 | B7: Basic | C7: Facilities | D7: Facade | E7: "Customer Parking" signs are available, undamaged and well maintained | F7: GM | G7: SALES MANAGER | H7: YES | J7: > Accomplish Inspection Request > Submit & Follow up with PM > Monitor progress until completion > signs completion report | K7: PM | N7: =IF(NOT(H7="N/A"),B7,"N/A") -> Basic | O7: =IF(H7="YES",B7,IF(H7="N/A","N/A","NO")) -> Basic | P7: =IF(H7="YES",C7,IF(H7="N/A","N/A","NO")) -> Facilities
A8: 6 | B8: Standard | C8: Facilities | D8: Facade | E8: No new units "stock" parked in customer parking area. | F8: GM | G8: SALES MANAGER | H8: YES | N8: =IF(NOT(H8="N/A"),B8,"N/A") -> Standard | O8: =IF(H8="YES",B8,IF(H8="N/A","N/A","NO")) -> Standard | P8: =IF(H8="YES",C8,IF(H8="N/A","N/A","NO")) -> Facilities
A9: 7 | B9: Basic | C9: Facilities | D9: Facade | E9: PWD parking slot and ramp with railings should be unobstructed and painted with standard PWD Logo. | F9: GM | G9: SALES MANAGER | H9: YES | J9: > Accomplish Inspection Request > Submit & Follow up with PM > Monitor progress until completion > signs completion report | K9: PM | N9: =IF(NOT(H9="N/A"),B9,"N/A") -> Basic | O9: =IF(H9="YES",B9,IF(H9="N/A","N/A","NO")) -> Basic | P9: =IF(H9="YES",C9,IF(H9="N/A","N/A","NO")) -> Facilities
A10: 8 | B10: Basic | C10: Product Presentation and Test Drive | D10: Test Drive | E10: Test drive vehicle are maintained clean, fully functional and is readily available for use. | F10: GM | G10: SALES MANAGER | H10: YES | J10: > SM to advise BOM of any damage > BOM prepare request for PMS or damage repair and send to Inventory > BOM must maintain aTest drive monitoring file record which includes, km reading, PMS and damage record. > PMS interval will be based on prescribed km reading or prescribed months whichever comes first. | K10: INVENTORY | N10: =IF(NOT(H10="N/A"),B10,"N/A") -> Basic | O10: =IF(H10="YES",B10,IF(H10="N/A","N/A","NO")) -> Basic | P10: =IF(H10="YES",C10,IF(H10="N/A","N/A","NO")) -> Product Presentation and Test Drive
A11: 9 | B11: Beyond | C11: Product Presentation and Test Drive | D11: Test Drive | E11: > Test drive parking area with a roof (tent) should be installed in front of the showroom > Test drive advertisement with Dealer's contact number visibly displayed at the dealership | F11: GM | G11: SALES MANAGER | H11: NO | J11: > prepare request for tent design standards from marketing > submit purchase request with design to Purchasing | K11: MARKETING / PURCHASING | N11: =IF(NOT(H11="N/A"),B11,"N/A") -> Beyond | O11: =IF(H11="YES",B11,IF(H11="N/A","N/A","NO")) -> NO | P11: =IF(H11="YES",C11,IF(H11="N/A","N/A","NO")) -> NO
A12: 10 | B12: Standard | C12: Product Presentation and Test Drive | D12: Test Drive | E12: Test drive route map is available | F12: GM | G12: SALES MANAGER | H12: YES | J12: > check if route map is available > advise GM if no route map is available. > follow up until compliant. | K12: MARKETING | N12: =IF(NOT(H12="N/A"),B12,"N/A") -> Standard | O12: =IF(H12="YES",B12,IF(H12="N/A","N/A","NO")) -> Standard | P12: =IF(H12="YES",C12,IF(H12="N/A","N/A","NO")) -> Product Presentation and Test Drive
A13: 11 | B13: Standard | C13: Customer Engagement and Showroom Operations | D13: Greetings | E13: MMPC greeting standard is done by all dealer staff. | F13: GM | G13: SALES MANAGER | H13: YES | J13: > check for compliance > advise GM of non compliance. > follow up until compliant. | K13: GM | N13: =IF(NOT(H13="N/A"),B13,"N/A") -> Standard | O13: =IF(H13="YES",B13,IF(H13="N/A","N/A","NO")) -> Standard | P13: =IF(H13="YES",C13,IF(H13="N/A","N/A","NO")) -> Customer Engagement and Showroom Operations
A14: 12 | B14: Standard | C14: Customer Engagement and Showroom Operations | D14: Greetings | E14: Customers were escorted during the entrance and sent off with an umbrella service (if necessary). | F14: GM | G14: SALES MANAGER | H14: YES | J14: > check for compliance > advise GM of non compliance. > follow up until compliant. | K14: GM | N14: =IF(NOT(H14="N/A"),B14,"N/A") -> Standard | O14: =IF(H14="YES",B14,IF(H14="N/A","N/A","NO")) -> Standard | P14: =IF(H14="YES",C14,IF(H14="N/A","N/A","NO")) -> Customer Engagement and Showroom Operations
A15: 13 | B15: Standard | C15: Facilities | D15: Showroom Area | E15: Reception Desk is installed in the entrance following the VI Standards; desk is clean, organized, and free of unecessary items; accent wall remains free of any designs | F15: GM | G15: SALES MANAGER | H15: YES | J15: > check for compliance > advise GM of non compliance. > follow up until compliant. | K15: GM | N15: =IF(NOT(H15="N/A"),B15,"N/A") -> Standard | O15: =IF(H15="YES",B15,IF(H15="N/A","N/A","NO")) -> Standard | P15: =IF(H15="YES",C15,IF(H15="N/A","N/A","NO")) -> Facilities
A16: 14 | B16: Standard | C16: Facilities | D16: Showroom Area | E16: No duplicate vehicle model variants were displayed | F16: GM | G16: SALES MANAGER | H16: YES | J16: > check for compliance > advise GM of non compliance. > follow up until compliant. | K16: GM | N16: =IF(NOT(H16="N/A"),B16,"N/A") -> Standard | O16: =IF(H16="YES",B16,IF(H16="N/A","N/A","NO")) -> Standard | P16: =IF(H16="YES",C16,IF(H16="N/A","N/A","NO")) -> Facilities
A17: 15 | B17: Basic | C17: Facilities | D17: Showroom Area | E17: Display units are clean and in good condition (no dents, scratches, fingerprints, etc.) | F17: GM | G17: SALES MANAGER | H17: YES | J17: > check for compliance > advise GM of non compliance. > follow up until compliant. | K17: GM | N17: =IF(NOT(H17="N/A"),B17,"N/A") -> Basic | O17: =IF(H17="YES",B17,IF(H17="N/A","N/A","NO")) -> Basic | P17: =IF(H17="YES",C17,IF(H17="N/A","N/A","NO")) -> Facilities
A18: 16 | B18: Basic | C18: Facilities | D18: Showroom Area | E18: All displayed cars have their corresponding and updated specs stands. | F18: GM | G18: SALES MANAGER | H18: YES | J18: > check for compliance > advise GM of non compliance. > follow up until compliant. | K18: GM | N18: =IF(NOT(H18="N/A"),B18,"N/A") -> Basic | O18: =IF(H18="YES",B18,IF(H18="N/A","N/A","NO")) -> Basic | P18: =IF(H18="YES",C18,IF(H18="N/A","N/A","NO")) -> Facilities
A19: 17 | B19: Standard | C19: Facilities | D19: Dealer Training Facilities and Equipment Standards | E19: Training facility/room shall be within standard room size based on Circular NTD-STS-2024-010 | F19: GM | G19: SALES MANAGER | H19: YES | J19: > check for compliance > Accomplish Inspection Request > Submit & Follow up with PM > Monitor progress until completion > signs completion report | K19: DND | N19: =IF(NOT(H19="N/A"),B19,"N/A") -> Standard | O19: =IF(H19="YES",B19,IF(H19="N/A","N/A","NO")) -> Standard | P19: =IF(H19="YES",C19,IF(H19="N/A","N/A","NO")) -> Facilities
A20: 18 | B20: Standard | C20: Facilities | D20: Dealer Training Facilities and Equipment Standards | E20: Training facility/room shall have complete tools and equipment for training based on Circular NTD-STS-2024-010 | F20: GM | G20: SALES MANAGER | H20: YES | J20: > check for compliance > advise GM of non compliance. > follow up until compliant. | K20: GM | N20: =IF(NOT(H20="N/A"),B20,"N/A") -> Standard | O20: =IF(H20="YES",B20,IF(H20="N/A","N/A","NO")) -> Standard | P20: =IF(H20="YES",C20,IF(H20="N/A","N/A","NO")) -> Facilities
... A32: 30 | B32: Standard | C32: Customer Engagement and Showroom Operations | D32: Showroom Area | E32: Showroom and customer lounge have designated amenity corner with the required signage | F32: GM | G32: SALES MANAGER | H32: YES | J32: > check for compliance > Accomplish Inspection Request > Submit & Follow up with PM > Monitor progress until completion > signs completion report | K32: CE CENTRAL | N32: =IF(NOT(H32="N/A"),B32,"N/A") -> Standard | O32: =IF(H32="YES",B32,IF(H32="N/A","N/A","NO")) -> Standard | P32: =IF(H32="YES",C32,IF(H32="N/A","N/A","NO")) -> Customer Engagement and Showroom Operations
A33: 31 | B33: Standard | C33: Customer Engagement and Showroom Operations | D33: Showroom Area | E33: Amenity corner has minimum of 3 beverage options available (water, juice, coffee, etc.) | F33: GM | G33: SALES MANAGER | H33: YES | I33: complete amenities | J33: > check for compliance > follow up request for replenishment from GM > BOM to replenish items | K33: GM | N33: =IF(NOT(H33="N/A"),B33,"N/A") -> Standard | O33: =IF(H33="YES",B33,IF(H33="N/A","N/A","NO")) -> Standard | P33: =IF(H33="YES",C33,IF(H33="N/A","N/A","NO")) -> Customer Engagement and Showroom Operations
A34: 32 | B34: Standard | C34: Customer Engagement and Showroom Operations | D34: Showroom Area | E34: Amenity corner has available snacks (biscuits, cupcakes, candies) | F34: GM | G34: SALES MANAGER | H34: YES | J34: > check for compliance > follow up request for replenishment from GM > BOM to replenish items | K34: GM | N34: =IF(NOT(H34="N/A"),B34,"N/A") -> Standard | O34: =IF(H34="YES",B34,IF(H34="N/A","N/A","NO")) -> Standard | P34: =IF(H34="YES",C34,IF(H34="N/A","N/A","NO")) -> Customer Engagement and Showroom Operations
A35: 33 | B35: Beyond | C35: Customer Engagement and Showroom Operations | D35: Showroom Area | E35: Sales Executives proactively offer beverages, snacks, Wi-Fi access, and lounge entertainment (TV) | F35: GM | G35: SALES MANAGER | H35: NO | J35: > check for compliance > advise GM of non compliance. > follow up until compliant. | K35: GM | N35: =IF(NOT(H35="N/A"),B35,"N/A") -> Beyond | O35: =IF(H35="YES",B35,IF(H35="N/A","N/A","NO")) -> NO | P35: =IF(H35="YES",C35,IF(H35="N/A","N/A","NO")) -> NO
A36: 34 | B36: Standard | C36: Facilities | D36: Showroom Area | E36: Rest Rooms must have clean water supply, toilet bowl, sink, urinal, bidet, trash cans, tissue, paper towel or hand dryer, and hand wash soap; no foul smell | F36: GM | G36: SALES MANAGER | H36: YES | J36: > check for compliance > Remind utility personnel of daily 5S task. | K36: GM | N36: =IF(NOT(H36="N/A"),B36,"N/A") -> Standard | O36: =IF(H36="YES",B36,IF(H36="N/A","N/A","NO")) -> Standard | P36: =IF(H36="YES",C36,IF(H36="N/A","N/A","NO")) -> Facilities
A37: 35 | B37: Standard | C37: Sales Operation Management | D37: Sales Operation | E37: Availability of Sales Performance Control Board with correct format /pattern and updated with corresponding progress indicator. | F37: GM | G37: SALES MANAGER | H37: YES | J37: > check for compliance > advise GM of non compliance. > follow up until compliant. | K37: GM | N37: =IF(NOT(H37="N/A"),B37,"N/A") -> Standard | O37: =IF(H37="YES",B37,IF(H37="N/A","N/A","NO")) -> Standard | P37: =IF(H37="YES",C37,IF(H37="N/A","N/A","NO")) -> Sales Operation Management
A38: 36 | B38: Standard | C38: Sales Operation Management | D38: Sales Operation | E38: Availability of sales activity with 2 months rolling plan, including SE duties. | F38: GM | G38: SALES MANAGER | H38: YES | J38: > check for compliance > advise GM of non compliance. > follow up until compliant. | K38: GM | N38: =IF(NOT(H38="N/A"),B38,"N/A") -> Standard | O38: =IF(H38="YES",B38,IF(H38="N/A","N/A","NO")) -> Standard | P38: =IF(H38="YES",C38,IF(H38="N/A","N/A","NO")) -> Sales Operation Management
A39: 37 | B39: Standard | C39: Sales Operation Management | D39: Sales Operation | E39: Conduct Gap analysis | F39: GM | G39: SALES MANAGER | H39: YES | J39: > refer to GM | K39: GENERAL MANAGER | N39: =IF(NOT(H39="N/A"),B39,"N/A") -> Standard | O39: =IF(H39="YES",B39,IF(H39="N/A","N/A","NO")) -> Standard | P39: =IF(H39="YES",C39,IF(H39="N/A","N/A","NO")) -> Sales Operation Management
A40: 38 | B40: Standard | C40: Product Presentation and Test Drive | D40: Sales Operation | E40: Low-performing SEs based on Sales and SSI Performance are identified and given corrective measures. | F40: GM | G40: SALES MANAGER | H40: YES | J40: > refer to GM | K40: GENERAL MANAGER CE CENTRAL | N40: =IF(NOT(H40="N/A"),B40,"N/A") -> Standard | O40: =IF(H40="YES",B40,IF(H40="N/A","N/A","NO")) -> Standard | P40: =IF(H40="YES",C40,IF(H40="N/A","N/A","NO")) -> Product Presentation and Test Drive
A41: 39 | B41: Standard | C41: Lead Generation and Management | D41: Sales Operation | E41: Check plan including area setting, evaluation of the area and assigned SE | F41: GM | G41: SALES MANAGER | H41: YES | J41: > refer to GM | K41: N/A | N41: =IF(NOT(H41="N/A"),B41,"N/A") -> Standard | O41: =IF(H41="YES",B41,IF(H41="N/A","N/A","NO")) -> Standard | P41: =IF(H41="YES",C41,IF(H41="N/A","N/A","NO")) -> Lead Generation and Management
A42: 40 | B42: Beyond | C42: Lead Generation and Management | D42: Sales Operation | E42: Conduct Prospect Party atleast once a year | F42: GM | G42: SALES MANAGER | H42: NO | J42: > refer to GM | K42: MARKETING | N42: =IF(NOT(H42="N/A"),B42,"N/A") -> Beyond | O42: =IF(H42="YES",B42,IF(H42="N/A","N/A","NO")) -> NO | P42: =IF(H42="YES",C42,IF(H42="N/A","N/A","NO")) -> NO
A43: 41 | B43: Beyond | C43: Lead Generation and Management | D43: Sales Operation | E43: Conduct Key Opinion Leaders (KOLs) atleast once a year | F43: GM | G43: SALES MANAGER | H43: NO | J43: > refer to GM | K43: MARKETING | N43: =IF(NOT(H43="N/A"),B43,"N/A") -> Beyond | O43: =IF(H43="YES",B43,IF(H43="N/A","N/A","NO")) -> NO | P43: =IF(H43="YES",C43,IF(H43="N/A","N/A","NO")) -> NO
A44: 42 | B44: Standard | C44: Manpower | D44: SE Process | E44: Sales Executives wear the proper uniform (showroom duty, vehicle release, or field duty attire) | F44: GM | G44: SALES MANAGER | H44: YES | J44: > check for compliance > advise GM of non compliance. > follow up until compliant. | K44: GENERAL MANAGER | N44: =IF(NOT(H44="N/A"),B44,"N/A") -> Standard | O44: =IF(H44="YES",B44,IF(H44="N/A","N/A","NO")) -> Standard | P44: =IF(H44="YES",C44,IF(H44="N/A","N/A","NO")) -> Manpower
A45: 43 | B45: Standard | C45: Sales Operation Management | D45: SE Process | E45: Sales Executives are well informed on the structure of SPC and targets are cascaded. | F45: GM | G45: SALES MANAGER | H45: YES | J45: > refer to GM | K45: GENERAL MANAGER | N45: =IF(NOT(H45="N/A"),B45,"N/A") -> Standard | O45: =IF(H45="YES",B45,IF(H45="N/A","N/A","NO")) -> Standard | P45: =IF(H45="YES",C45,IF(H45="N/A","N/A","NO")) -> Sales Operation Management
... A70: 68 | B70: Standard | C70: Vehicle Release Management | D70: Vehicle Delivery | E70: Release area is clean and with good atmosphere | F70: GM | G70: SALES MANAGER | H70: YES | J70: > check for compliance > Remind utility personnel of daily 5S task. | K70: BOM | N70: =IF(NOT(H70="N/A"),B70,"N/A") -> Standard | O70: =IF(H70="YES",B70,IF(H70="N/A","N/A","NO")) -> Standard | P70: =IF(H70="YES",C70,IF(H70="N/A","N/A","NO")) -> Vehicle Release Management
A71: 69 | B71: Beyond | C71: Vehicle Release Management | D71: Vehicle Delivery | E71: Releasing Area is inside the showroom | F71: GM | G71: SALES MANAGER | H71: NO | K71: GENERAL MANAGER | N71: =IF(NOT(H71="N/A"),B71,"N/A") -> Beyond | O71: =IF(H71="YES",B71,IF(H71="N/A","N/A","NO")) -> NO | P71: =IF(H71="YES",C71,IF(H71="N/A","N/A","NO")) -> NO | S71: ALL DEALER RELEASING AREA IS OUTSIDE THE SHOWROOM
A72: 70 | B72: Standard | C72: Lead Generation and Management | D72: Monitoring | E72: Leads Database contains customer data from the past 5 years and is being monitored | F72: GM | G72: SALES MANAGER | H72: YES | J72: > refer to GM | K72: CENTRAL ADMIN | N72: =IF(NOT(H72="N/A"),B72,"N/A") -> Standard | O72: =IF(H72="YES",B72,IF(H72="N/A","N/A","NO")) -> Standard | P72: =IF(H72="YES",C72,IF(H72="N/A","N/A","NO")) -> Lead Generation and Management | S72: MMPC YANA SYSTEM
A73: 71 | B73: Beyond | C73: Lead Generation and Management | D73: Monitoring | E73: Fleet Account Monitoring is available and updated | F73: GM | G73: SALES MANAGER | H73: NO | J73: > refer to GM | N73: =IF(NOT(H73="N/A"),B73,"N/A") -> Beyond | O73: =IF(H73="YES",B73,IF(H73="N/A","N/A","NO")) -> NO | P73: =IF(H73="YES",C73,IF(H73="N/A","N/A","NO")) -> NO
A74: 72 | B74: Standard | C74: Vehicle Release Management | D74: Monitoring | E74: PDI is done 3 days prior to customer release | F74: GM | G74: SALES MANAGER | H74: YES | J74: > check for compliance > system based release timing | K74: LOGISTIC | N74: =IF(NOT(H74="N/A"),B74,"N/A") -> Standard | O74: =IF(H74="YES",B74,IF(H74="N/A","N/A","NO")) -> Standard | P74: =IF(H74="YES",C74,IF(H74="N/A","N/A","NO")) -> Vehicle Release Management
A75: 73 | B75: Standard | C75: Vehicle Release Management | D75: Monitoring | E75: Daily Release Monitoring is being utilized. | F75: GM | G75: SALES MANAGER | H75: YES | J75: > check for compliance > system based release monitoring | K75: GENERAL MANAGER | N75: =IF(NOT(H75="N/A"),B75,"N/A") -> Standard | O75: =IF(H75="YES",B75,IF(H75="N/A","N/A","NO")) -> Standard | P75: =IF(H75="YES",C75,IF(H75="N/A","N/A","NO")) -> Vehicle Release Management
A76: 74 | B76: Standard | C76: Post-Release Customer Management | D76: Monitoring | E76: Birthday/Anniversary Message Greeting was sent to customers with proper monitoring and tracking | F76: GM | G76: SALES MANAGER | H76: YES | J76: > Assigned to CE Central | K76: CE CENTRAL | N76: =IF(NOT(H76="N/A"),B76,"N/A") -> Standard | O76: =IF(H76="YES",B76,IF(H76="N/A","N/A","NO")) -> Standard | P76: =IF(H76="YES",C76,IF(H76="N/A","N/A","NO")) -> Post-Release Customer Management
...

Sheet Summary
A1: SALES STANDARDS COMPLIANCE AUDIT FORM FY2025
B3: Dealer: | C3: =VLOOKUP(C5,Sheet1!A:B,2,FALSE) -> #N/A | F3: Date:
B5: Outlet: | F5: Auditor:
A7: Overall Audit Score
A8: No. | B8: Category | D8: Total | E8: Score | F8: % Score | G8: Rating
A9: 1 | B9: Basic | D9: =COUNTIF('Main Form'!$B$3:$B$92,Summary!B9)-COUNTIFS('Main Form'!$B$3:$B$92,Summary!B9,'Main Form'!$O$3:$O$92,"N/A") -> 14 | E9: =COUNTIF('Main Form'!$O$3:$O$92,B9) -> 14 | F9: =E9/D9 -> 1 | G9: =IF(F9<100%,"FAIL", "PASS") -> PASS
A10: 2 | B10: Standard | D10: =COUNTIF('Main Form'!$B$3:$B$92,Summary!B10)-COUNTIFS('Main Form'!$B$3:$B$92,Summary!B10,'Main Form'!$O$3:$O$92,"N/A") -> 66 | E10: =COUNTIF('Main Form'!$O$3:$O$92,B10) -> 58 | F10: =E10/D10 -> 0.87878788 | G10: =IF(F10<80%,"FAIL", "PASS") -> PASS
A11: 3 | B11: Beyond | D11: =COUNTIF('Main Form'!$B$3:$B$92,Summary!B11)-COUNTIFS('Main Form'!$B$3:$B$92,Summary!B11,'Main Form'!$O$3:$O$92,"N/A") -> 10 | E11: 10 | F11: =E11/D11 -> 1
A12: TOTAL: | D12: =SUM(D9:D11) -> 90 | E12: =SUM(E9:E11) -> 82 | F12: =E12/D12 -> 0.91111111 | G12: =IF(F12<80%,"FAIL",IF(OR(G9="FAIL",G10="FAIL",G11="FAIL"),"FAIL","PASS")) -> PASS
A14: Compliance Per Category
A15: No. | B15: Coverage | D15: Total | E15: Score | F15: % Score
A16: 1 | B16: Facilities | D16: =COUNTIF('Main Form'!$C$3:$C$92,Summary!B16)-COUNTIFS('Main Form'!$C$3:$C$92,Summary!B16,'Main Form'!$P$3:$P$92,"N/A") -> 23 | E16: =COUNTIFS('Main Form'!$P$3:$P$92,B16) -> 23 | F16: =E16/D16 -> 1
A17: 2 | B17: Systems | D17: =COUNTIF('Main Form'!$C$3:$C$92,Summary!B17)-COUNTIFS('Main Form'!$C$3:$C$92,Summary!B17,'Main Form'!$P$3:$P$92,"N/A") -> 4 | E17: =COUNTIFS('Main Form'!$P$3:$P$92,B17) -> 2 | F17: =E17/D17 -> 0.5
A18: 3 | B18: Manpower | D18: =COUNTIF('Main Form'!$C$3:$C$92,Summary!B18)-COUNTIFS('Main Form'!$C$3:$C$92,Summary!B18,'Main Form'!$P$3:$P$92,"N/A") -> 5 | E18: =COUNTIFS('Main Form'!$P$3:$P$92,B18) -> 4 | F18: =E18/D18 -> 0.8
A19: 4 | B19: Lead Generation and Management | D19: =COUNTIF('Main Form'!$C$3:$C$92,Summary!B19)-COUNTIFS('Main Form'!$C$3:$C$92,Summary!B19,'Main Form'!$P$3:$P$92,"N/A") -> 9 | E19: =COUNTIFS('Main Form'!$P$3:$P$92,B19) -> 5 | F19: =E19/D19 -> 0.55555556
A20: 5 | B20: Needs Analysis | D20: =COUNTIF('Main Form'!$C$3:$C$92,Summary!B20)-COUNTIFS('Main Form'!$C$3:$C$92,Summary!B20,'Main Form'!$P$3:$P$92,"N/A") -> 3 | E20: =COUNTIFS('Main Form'!$P$3:$P$92,B20) -> 3 | F20: =E20/D20 -> 1
A21: 6 | B21: Customer Engagement and Showroom Operations | D21: =COUNTIF('Main Form'!$C$3:$C$92,Summary!B21)-COUNTIFS('Main Form'!$C$3:$C$92,Summary!B21,'Main Form'!$P$3:$P$92,"N/A") -> 8 | E21: =COUNTIFS('Main Form'!$P$3:$P$92,B21) -> 6 | F21: =E21/D21 -> 0.75
A22: 7 | B22: Product Presentation and Test Drive | D22: =COUNTIF('Main Form'!$C$3:$C$92,Summary!B22)-COUNTIFS('Main Form'!$C$3:$C$92,Summary!B22,'Main Form'!$P$3:$P$92,"N/A") -> 6 | E22: =COUNTIFS('Main Form'!$P$3:$P$92,B22) -> 5 | F22: =E22/D22 -> 0.83333333
A23: 8 | B23: Deal and Closing Management | D23: =COUNTIF('Main Form'!$C$3:$C$92,Summary!B23)-COUNTIFS('Main Form'!$C$3:$C$92,Summary!B23,'Main Form'!$P$3:$P$92,"N/A") -> 2 | E23: =COUNTIFS('Main Form'!$P$3:$P$92,B23) -> 2 | F23: =E23/D23 -> 1
A24: 9 | B24: Application Process Support | D24: =COUNTIF('Main Form'!$C$3:$C$92,Summary!B24)-COUNTIFS('Main Form'!$C$3:$C$92,Summary!B24,'Main Form'!$P$3:$P$92,"N/A") -> 3 | E24: =COUNTIFS('Main Form'!$P$3:$P$92,B24) -> 3 | F24: =E24/D24 -> 1
A25: 10 | B25: Sales Operation Management | D25: =COUNTIF('Main Form'!$C$3:$C$92,Summary!B25)-COUNTIFS('Main Form'!$C$3:$C$92,Summary!B25,'Main Form'!$P$3:$P$92,"N/A") -> 8 | E25: =COUNTIFS('Main Form'!$P$3:$P$92,B25) -> 8 | F25: =E25/D25 -> 1
A26: 11 | B26: Vehicle Release Management | D26: =COUNTIF('Main Form'!$C$3:$C$92,Summary!B26)-COUNTIFS('Main Form'!$C$3:$C$92,Summary!B26,'Main Form'!$P$3:$P$92,"N/A") -> 11 | E26: =COUNTIFS('Main Form'!$P$3:$P$92,B26) -> 9 | F26: =E26/D26 -> 0.81818182
A27: 12 | B27: Post-Release Customer Management | D27: =COUNTIF('Main Form'!$C$3:$C$92,Summary!B27)-COUNTIFS('Main Form'!$C$3:$C$92,Summary!B27,'Main Form'!$P$3:$P$92,"N/A") -> 3 | E27: =COUNTIFS('Main Form'!$P$3:$P$92,B27) -> 2 | F27: =E27/D27 -> 0.66666667
A28: 13 | B28: Mandatory Reports | D28: =COUNTIF('Main Form'!$C$3:$C$92,Summary!B28)-COUNTIFS('Main Form'!$C$3:$C$92,Summary!B28,'Main Form'!$P$3:$P$92,"N/A") -> 5 | E28: =COUNTIFS('Main Form'!$P$3:$P$92,B28) -> 0 | F28: =E28/D28 -> 0
A29: Total: | D29: =SUM(D16:D28) -> 90 | E29: =SUM(E16:E28) -> 72 | F29: =E29/D29 -> 0.8

Sheet How To Check
A2: No. | B2: Category | C2: Coverage | D2: Subject | E2: Check Item | F2: How to Check | G2: Column1
A3: 1 | B3: Basic | C3: Facilities | D3: Facade | E3: Fascia or badge sign and letterings are complete, undamaged, clean, no watermarks, no obstructions, no discoloration and stains | F3: 1. Check through observation if it meets the MMPC VI Standard Requirements
A4: 2 | B4: Basic | C4: Facilities | D4: Facade | E4: Pylon (Single/Two-Post / Tower / Wall Projecting) sign/s and letterings are complete, undamaged, clean, no watermarks, no obstructions, no discoloration and stains | F4: 1. Check through observation if it meets the MMPC VI Standard Requirements
A5: 3 | B5: Basic | C5: Facilities | D5: Facade | E5: All exterior Visual Identity including building walls, exterior paint and finishes, are clean and free from damage. | F5: 1. Check through observation if it meets the MMPC VI Standard Requirements
A6: 4 | B6: Basic | C6: Facilities | D6: Facade | E6: Showroom glass is clean, free from cracks, scratches, damage, dust, stains and water marks | F6: 1. Check through observation if compliant
A7: 5 | B7: Basic | C7: Facilities | D7: Facade | E7: "Customer Parking" signs are available, undamaged and well maintained | F7: 1. Check through observation if it meets the MMPC VI Standard Requirements
A8: 6 | B8: Standard | C8: Facilities | D8: Facade | E8: No new units "stock" parked in customer parking area. | F8: 1. Check through observation if compliant
A9: 7 | B9: Basic | C9: Facilities | D9: Facade | E9: PWD parking slot and ramp with railings should be unobstructed and painted with standard PWD Logo. | F9: 1. Check through observation if compliant
A10: 8 | B10: Basic | C10: Product Presentation and Test Drive | D10: Test Drive | E10: Test drive vehicle are maintained clean, fully functional and is readily available for use. | F10: 1. Check if the designated test drive units is compliant
A11: 9 | B11: Beyond | C11: Product Presentation and Test Drive | D11: Test Drive | E11: > Test drive parking area with a roof (tent) should be installed in front of the showroom > Test drive advertisement with Dealer's contact number visibly displayed at the dealership | F11: 1. Check through observation if the testdrive advertisement and dealership contact details are updated
A12: 10 | B12: Standard | C12: Product Presentation and Test Drive | D12: Test Drive | E12: Test drive route map is available | F12: 1. Check if the testdrive route map is available at the showroom area 2. Check if there are 2 - 3 test drive route map available
A13: 11 | B13: Standard | C13: Customer Engagement and Showroom Operations | D13: Greetings | E13: MMPC greeting standard is done by all dealer staff. | F13: 1. Check if all dealer staff follow the standard greeting (Smile, Greet & Bow) and are consistently done.
A14: 12 | B14: Standard | C14: Customer Engagement and Showroom Operations | D14: Greetings | E14: Customers were escorted during the entrance and sent off with an umbrella service (if necessary). | F14: 1. Check through observation if the available umbrella at the dealership is either within MMPC branding or has no branding/logos.
... A92: 90 | B92: Standard | C92: Manpower | D92: Documentation | E92: Sales Training Accreditation monthly report is updated by assigned dealer personnel | F92: 1. Check if PIC submitted monthly report
B93: Total

Sheet Pivot
B2: Main Category
A3: Subject | B3: Basic | C3: Standard | D3: Beyond | E3: Grand Total
A4: Workshop Driveway
A5: Workshop Maintenance
A6: Tools Storage Room
A7: Components Repair Room
A8: Waste Oil Storage
A9: Warranty Parts Storage
A10: Scrapped Parts Storage
A11: Dismantled Parts Storage
A12: Service Reception Area
A13: CRM Requirements
A14: Service Documents
A15: Employee Facilities
... A66: Grand Total

Sheet Data sheet
A1: Branch | B1: Dealer Group
A2: Bajada | B2: Karasia Incorporated
A3: Bulua | B3: Fast Autotoworld Philippines Corporation - Mindanao
A4: Cebu South | B4: Fast Autotoworld Philippines Corporation - Visayas
A5: Commonwealth | B5: Peak Motors Phils. Incorporated
A6: Dasmariñas | B6: Jabez Motors Corporation
A7: Gorordo | B7: Gateway Motors Cebu, Inc.
A8: Kalookan | B8: Union Motors Corporation
A9: Lucena | B9: Mizukawa Motors Corp.
A10: Mactan | B10: Fast Autotoworld Philippines Corporation - Visayas
A11: Manila Bay | B11: Peak Motors Phils. Incorporated
A12: Marcos Highway | B12: Diamond Motors Corporation
... A18: Sucat | B18: Gateway Motors Cebu, Inc.
A19: #VALUE! | B19: Citimotors Incorporation
A20: #VALUE! | B20: Blulebird Motor Corp.
A21: #VALUE! | B21: Avescor Motors Incorporated
A22: #VALUE! | B22: Motor Plaza Incorporated
A23: #VALUE! | B23: Freeway Motor Sales - Baliuag
A24: #VALUE! | B24: Mizukawa Motors Corp.
A25: #VALUE! | B25: Fast Autotoworld Philippines Corporation - Mindanao
A26: #VALUE! | B26: Freeway Motor Sales - Cabanatuan
A27: #VALUE! | B27: Fast Autotoworld Philippines Corporation - Mindanao
A28: #VALUE! | B28: Motor Plaza Incorporated
A29: #VALUE! | B29: Alpine Motors Corporation
A30: #VALUE! | B30: SJ Legacy Motors, Inc.
... A68: #VALUE! | B68: Zamboanga Motors Incorporated
C72: YES
C73: NO
C74: N/A
C76: A
C77: B
C79: Y
C80: N

Sheet Sheet1
A1: Branch | B1: Dealer Group
A2: #VALUE! | B2: Citimotors Incorporation
A3: #VALUE! | B3: Blulebird Motor Corp.
A4: #VALUE! | B4: Avescor Motors Incorporated
A5: #VALUE! | B5: Motor Plaza Incorporated
A6: Bajada | B6: Karasia Incorporated
A7: Kalookan | B7: Union Motors Corporation
A8: #VALUE! | B8: Freeway Motor Sales - Baliuag
A9: #VALUE! | B9: Mizukawa Motors Corp.
A10: Bulua | B10: Fast Autotoworld Philippines Corporation - Mindanao
A11: #VALUE! | B11: Fast Autotoworld Philippines Corporation - Mindanao
A12: #VALUE! | B12: Freeway Motor Sales - Cabanatuan
A13: #VALUE! | B13: Fast Autotoworld Philippines Corporation - Mindanao
A14: #VALUE! | B14: Motor Plaza Incorporated
A15: #VALUE! | B15: Alpine Motors Corporation
A16: Cebu South | B16: Fast Autotoworld Philippines Corporation - Visayas
A17: Commonwealth | B17: Peak Motors Phils. Incorporated
A18: #VALUE! | B18: SJ Legacy Motors, Inc.
A19: Dasmariñas | B19: Jabez Motors Corporation
A20: #VALUE! | B20: Fast Autotoworld Philippines Corporation - Visayas
A21: #VALUE! | B21: Gateway Motors Cebu, Inc.
A22: Manila Bay | B22: Peak Motors Phils. Incorporated
A23: #VALUE! | B23: Mindanao Integrated Commercial Enterprises Inc.
A24: Gorordo | B24: Gateway Motors Cebu, Inc.
A25: #VALUE! | B25: Mizukawa Motors Corp.
A26: #VALUE! | B26: Avescor Motors Incorporated
A27: #VALUE! | B27: Mizukawa Motors Corp.
A28: #VALUE! | B28: Freeway Motor Sales - Cabanatuan
A29: #VALUE! | B29: Peak Motors Phils. Incorporated
A30: #VALUE! | B30: Mindanao Integrated Commercial Enterprises Inc.
A31: #VALUE! | B31: Motor Plaza Incorporated
A32: #VALUE! | B32: North Alliance Motors Corporation
A33: #VALUE! | B33: Citimotors Incorporation
A34: #VALUE! | B34: Super Fast Motors Corporation
A35: Lucena | B35: Mizukawa Motors Corp.
A36: Mactan | B36: Fast Autotoworld Philippines Corporation - Visayas
A37: #VALUE! | B37: Citimotors Incorporation
A38: #VALUE! | B38: Carworld Incorporated
A39: #VALUE! | B39: Fast Autotoworld Philippines Corporation - Visayas
A40: #VALUE! | B40: Grand Canyon Multi Holdings Inc.
...
